[2023-08-25T17:44:24.345+0000] {taskinstance.py:1159} INFO - Dependencies all met for dep_context=non-requeueable deps ti=<TaskInstance: gaas_etl.etl_event scheduled__2023-08-25T10:46:00+00:00 [queued]>
[2023-08-25T17:44:24.425+0000] {taskinstance.py:1159} INFO - Dependencies all met for dep_context=requeueable deps ti=<TaskInstance: gaas_etl.etl_event scheduled__2023-08-25T10:46:00+00:00 [queued]>
[2023-08-25T17:44:24.428+0000] {taskinstance.py:1361} INFO - Starting attempt 1 of 1
[2023-08-25T17:44:24.682+0000] {taskinstance.py:1382} INFO - Executing <Task(PythonOperator): etl_event> on 2023-08-25 10:46:00+00:00
[2023-08-25T17:44:24.734+0000] {standard_task_runner.py:57} INFO - Started process 215459 to run task
[2023-08-25T17:44:24.803+0000] {standard_task_runner.py:84} INFO - Running: ['airflow', 'tasks', 'run', 'gaas_etl', 'etl_event', 'scheduled__2023-08-25T10:46:00+00:00', '--job-id', '39', '--raw', '--subdir', 'DAGS_FOLDER/dag_etl.py', '--cfg-path', '/tmp/tmpenn0d52v']
[2023-08-25T17:44:24.849+0000] {standard_task_runner.py:85} INFO - Job 39: Subtask etl_event
[2023-08-25T17:44:25.433+0000] {task_command.py:415} INFO - Running <TaskInstance: gaas_etl.etl_event scheduled__2023-08-25T10:46:00+00:00 [running]> on host data-system.us-central1-a.c.data-system-392010.internal
[2023-08-25T17:44:26.051+0000] {taskinstance.py:1660} INFO - Exporting env vars: AIRFLOW_CTX_DAG_EMAIL='hungnm15012002@gmail.com' AIRFLOW_CTX_DAG_OWNER='hungnm' AIRFLOW_CTX_DAG_ID='gaas_etl' AIRFLOW_CTX_TASK_ID='etl_event' AIRFLOW_CTX_EXECUTION_DATE='2023-08-25T10:46:00+00:00' AIRFLOW_CTX_TRY_NUMBER='1' AIRFLOW_CTX_DAG_RUN_ID='scheduled__2023-08-25T10:46:00+00:00'
[2023-08-25T17:44:26.171+0000] {dag_etl.py:116} INFO - Extracting event...
[2023-08-25T17:44:45.722+0000] {extract.py:36} INFO - Request time: 0:00:19.544601
[2023-08-25T17:44:58.273+0000] {extract.py:42} INFO - Create DataFrame time: 0:00:12.538066
[2023-08-25T17:44:58.602+0000] {dag_etl.py:119} INFO - Complete extract event: 0:00:32.431805
[2023-08-25T17:44:58.604+0000] {dag_etl.py:121} INFO - Transforming action...
[2023-08-25T17:44:59.047+0000] {logging_mixin.py:151} WARNING - /home/data-engineer/GAAS_Data_System/ETL/transform.py:52 SettingWithCopyWarning:
A value is trying to be set on a copy of a slice from a DataFrame.
Try using .loc[row_indexer,col_indexer] = value instead

See the caveats in the documentation: https://pandas.pydata.org/pandas-docs/stable/user_guide/indexing.html#returning-a-view-versus-a-copy
[2023-08-25T17:45:00.096+0000] {logging_mixin.py:151} WARNING - /home/data-engineer/GAAS_Data_System/ETL/transform.py:53 SettingWithCopyWarning:
A value is trying to be set on a copy of a slice from a DataFrame.
Try using .loc[row_indexer,col_indexer] = value instead

See the caveats in the documentation: https://pandas.pydata.org/pandas-docs/stable/user_guide/indexing.html#returning-a-view-versus-a-copy
[2023-08-25T17:54:34.948+0000] {local_task_job_runner.py:205} ERROR - Heartbeat time limit exceeded!
[2023-08-25T17:54:35.136+0000] {process_utils.py:131} INFO - Sending 15 to group 215459. PIDs of all processes in the group: [215459]
[2023-08-25T17:54:35.136+0000] {process_utils.py:86} INFO - Sending the signal 15 to group 215459
[2023-08-25T17:54:35.166+0000] {taskinstance.py:1632} ERROR - Received SIGTERM. Terminating subprocesses.
[2023-08-25T17:54:35.201+0000] {taskinstance.py:1943} ERROR - Task failed with exception
Traceback (most recent call last):
  File "/home/data-engineer/GAAS_Data_System/Airflow/dags/dag_etl.py", line 122, in etl_event
    df_action = transform_events(event_data,'action')
  File "/home/data-engineer/GAAS_Data_System/ETL/transform.py", line 57, in transform_events
    value_df[time_columns] = value_df[time_columns].apply(lambda x: to_datetime(x), axis=1, result_type='expand')
  File "/home/data-engineer/GAAS_Data_System/venv/lib/python3.10/site-packages/pandas/core/frame.py", line 9423, in apply
    return op.apply().__finalize__(self, method="apply")
  File "/home/data-engineer/GAAS_Data_System/venv/lib/python3.10/site-packages/pandas/core/apply.py", line 678, in apply
    return self.apply_standard()
  File "/home/data-engineer/GAAS_Data_System/venv/lib/python3.10/site-packages/pandas/core/apply.py", line 798, in apply_standard
    results, res_index = self.apply_series_generator()
  File "/home/data-engineer/GAAS_Data_System/venv/lib/python3.10/site-packages/pandas/core/apply.py", line 814, in apply_series_generator
    results[i] = self.f(v)
  File "/home/data-engineer/GAAS_Data_System/ETL/transform.py", line 57, in <lambda>
    value_df[time_columns] = value_df[time_columns].apply(lambda x: to_datetime(x), axis=1, result_type='expand')
  File "/home/data-engineer/GAAS_Data_System/ETL/transform.py", line 16, in to_datetime
    row['ts'] = pd.to_datetime(row['ts'], unit='ms')
  File "/home/data-engineer/GAAS_Data_System/venv/lib/python3.10/site-packages/pandas/core/tools/datetimes.py", line 1084, in to_datetime
    result = convert_listlike(np.array([arg]), format)[0]
  File "/home/data-engineer/GAAS_Data_System/venv/lib/python3.10/site-packages/pandas/core/tools/datetimes.py", line 427, in _convert_listlike_datetimes
    return _to_datetime_with_unit(arg, unit, name, utc, errors)
  File "/home/data-engineer/GAAS_Data_System/venv/lib/python3.10/site-packages/pandas/core/tools/datetimes.py", line 545, in _to_datetime_with_unit
    result = DatetimeIndex(arr, name=name)
  File "/home/data-engineer/GAAS_Data_System/venv/lib/python3.10/site-packages/pandas/core/indexes/datetimes.py", line 306, in __new__
    def __new__(
  File "/home/data-engineer/GAAS_Data_System/venv/lib/python3.10/site-packages/airflow/models/taskinstance.py", line 1634, in signal_handler
    raise AirflowException("Task received SIGTERM signal")
airflow.exceptions.AirflowException: Task received SIGTERM signal

During handling of the above exception, another exception occurred:

Traceback (most recent call last):
  File "/home/data-engineer/GAAS_Data_System/venv/lib/python3.10/site-packages/airflow/operators/python.py", line 192, in execute
    return_value = self.execute_callable()
  File "/home/data-engineer/GAAS_Data_System/venv/lib/python3.10/site-packages/airflow/operators/python.py", line 209, in execute_callable
    return self.python_callable(*self.op_args, **self.op_kwargs)
  File "/home/data-engineer/GAAS_Data_System/Airflow/dags/dag_etl.py", line 148, in etl_event
    cache_process(greater, less, "events")
  File "/home/data-engineer/GAAS_Data_System/ETL/verify_func.py", line 27, in cache_process
    cache_df = pd.read_csv(cache_process_path)
  File "/home/data-engineer/GAAS_Data_System/venv/lib/python3.10/site-packages/pandas/io/parsers/readers.py", line 912, in read_csv
    return _read(filepath_or_buffer, kwds)
  File "/home/data-engineer/GAAS_Data_System/venv/lib/python3.10/site-packages/pandas/io/parsers/readers.py", line 577, in _read
    parser = TextFileReader(filepath_or_buffer, **kwds)
  File "/home/data-engineer/GAAS_Data_System/venv/lib/python3.10/site-packages/pandas/io/parsers/readers.py", line 1407, in __init__
    self._engine = self._make_engine(f, self.engine)
  File "/home/data-engineer/GAAS_Data_System/venv/lib/python3.10/site-packages/pandas/io/parsers/readers.py", line 1661, in _make_engine
    self.handles = get_handle(
  File "/home/data-engineer/GAAS_Data_System/venv/lib/python3.10/site-packages/pandas/io/common.py", line 859, in get_handle
    handle = open(
FileNotFoundError: [Errno 2] No such file or directory: '/home/data-engineer/GAAS_Data_System/ETL/cache_process/20230825'
[2023-08-25T17:54:35.816+0000] {taskinstance.py:1400} INFO - Marking task as FAILED. dag_id=gaas_etl, task_id=etl_event, execution_date=20230825T104600, start_date=20230825T174424, end_date=20230825T175435
[2023-08-25T17:54:38.002+0000] {logging_mixin.py:151} WARNING - /home/data-engineer/GAAS_Data_System/venv/lib/python3.10/site-packages/airflow/utils/email.py:154 RemovedInAirflow3Warning: Fetching SMTP credentials from configuration variables will be deprecated in a future release. Please set credentials using a connection instead.
[2023-08-25T17:54:38.011+0000] {configuration.py:1064} WARNING - section/key [smtp/smtp_user] not found in config
[2023-08-25T17:54:38.012+0000] {email.py:270} INFO - Email alerting: attempt 1
[2023-08-25T17:54:38.073+0000] {configuration.py:1064} WARNING - section/key [smtp/smtp_user] not found in config
[2023-08-25T17:54:38.074+0000] {email.py:270} INFO - Email alerting: attempt 1
[2023-08-25T17:54:38.074+0000] {taskinstance.py:2013} ERROR - Failed to send email to: ['hungnm15012002@gmail.com']
Traceback (most recent call last):
  File "/home/data-engineer/GAAS_Data_System/Airflow/dags/dag_etl.py", line 122, in etl_event
    df_action = transform_events(event_data,'action')
  File "/home/data-engineer/GAAS_Data_System/ETL/transform.py", line 57, in transform_events
    value_df[time_columns] = value_df[time_columns].apply(lambda x: to_datetime(x), axis=1, result_type='expand')
  File "/home/data-engineer/GAAS_Data_System/venv/lib/python3.10/site-packages/pandas/core/frame.py", line 9423, in apply
    return op.apply().__finalize__(self, method="apply")
  File "/home/data-engineer/GAAS_Data_System/venv/lib/python3.10/site-packages/pandas/core/apply.py", line 678, in apply
    return self.apply_standard()
  File "/home/data-engineer/GAAS_Data_System/venv/lib/python3.10/site-packages/pandas/core/apply.py", line 798, in apply_standard
    results, res_index = self.apply_series_generator()
  File "/home/data-engineer/GAAS_Data_System/venv/lib/python3.10/site-packages/pandas/core/apply.py", line 814, in apply_series_generator
    results[i] = self.f(v)
  File "/home/data-engineer/GAAS_Data_System/ETL/transform.py", line 57, in <lambda>
    value_df[time_columns] = value_df[time_columns].apply(lambda x: to_datetime(x), axis=1, result_type='expand')
  File "/home/data-engineer/GAAS_Data_System/ETL/transform.py", line 16, in to_datetime
    row['ts'] = pd.to_datetime(row['ts'], unit='ms')
  File "/home/data-engineer/GAAS_Data_System/venv/lib/python3.10/site-packages/pandas/core/tools/datetimes.py", line 1084, in to_datetime
    result = convert_listlike(np.array([arg]), format)[0]
  File "/home/data-engineer/GAAS_Data_System/venv/lib/python3.10/site-packages/pandas/core/tools/datetimes.py", line 427, in _convert_listlike_datetimes
    return _to_datetime_with_unit(arg, unit, name, utc, errors)
  File "/home/data-engineer/GAAS_Data_System/venv/lib/python3.10/site-packages/pandas/core/tools/datetimes.py", line 545, in _to_datetime_with_unit
    result = DatetimeIndex(arr, name=name)
  File "/home/data-engineer/GAAS_Data_System/venv/lib/python3.10/site-packages/pandas/core/indexes/datetimes.py", line 306, in __new__
    def __new__(
  File "/home/data-engineer/GAAS_Data_System/venv/lib/python3.10/site-packages/airflow/models/taskinstance.py", line 1634, in signal_handler
    raise AirflowException("Task received SIGTERM signal")
airflow.exceptions.AirflowException: Task received SIGTERM signal

During handling of the above exception, another exception occurred:

Traceback (most recent call last):
  File "/home/data-engineer/GAAS_Data_System/venv/lib/python3.10/site-packages/airflow/models/taskinstance.py", line 1518, in _run_raw_task
    self._execute_task_with_callbacks(context, test_mode, session=session)
  File "/home/data-engineer/GAAS_Data_System/venv/lib/python3.10/site-packages/airflow/models/taskinstance.py", line 1679, in _execute_task_with_callbacks
    result = self._execute_task(context, task_orig)
  File "/home/data-engineer/GAAS_Data_System/venv/lib/python3.10/site-packages/airflow/models/taskinstance.py", line 1750, in _execute_task
    result = execute_callable(context=context)
  File "/home/data-engineer/GAAS_Data_System/venv/lib/python3.10/site-packages/airflow/operators/python.py", line 192, in execute
    return_value = self.execute_callable()
  File "/home/data-engineer/GAAS_Data_System/venv/lib/python3.10/site-packages/airflow/operators/python.py", line 209, in execute_callable
    return self.python_callable(*self.op_args, **self.op_kwargs)
  File "/home/data-engineer/GAAS_Data_System/Airflow/dags/dag_etl.py", line 148, in etl_event
    cache_process(greater, less, "events")
  File "/home/data-engineer/GAAS_Data_System/ETL/verify_func.py", line 27, in cache_process
    cache_df = pd.read_csv(cache_process_path)
  File "/home/data-engineer/GAAS_Data_System/venv/lib/python3.10/site-packages/pandas/io/parsers/readers.py", line 912, in read_csv
    return _read(filepath_or_buffer, kwds)
  File "/home/data-engineer/GAAS_Data_System/venv/lib/python3.10/site-packages/pandas/io/parsers/readers.py", line 577, in _read
    parser = TextFileReader(filepath_or_buffer, **kwds)
  File "/home/data-engineer/GAAS_Data_System/venv/lib/python3.10/site-packages/pandas/io/parsers/readers.py", line 1407, in __init__
    self._engine = self._make_engine(f, self.engine)
  File "/home/data-engineer/GAAS_Data_System/venv/lib/python3.10/site-packages/pandas/io/parsers/readers.py", line 1661, in _make_engine
    self.handles = get_handle(
  File "/home/data-engineer/GAAS_Data_System/venv/lib/python3.10/site-packages/pandas/io/common.py", line 859, in get_handle
    handle = open(
FileNotFoundError: [Errno 2] No such file or directory: '/home/data-engineer/GAAS_Data_System/ETL/cache_process/20230825'

During handling of the above exception, another exception occurred:

Traceback (most recent call last):
  File "/home/data-engineer/GAAS_Data_System/venv/lib/python3.10/site-packages/airflow/models/taskinstance.py", line 2426, in email_alert
    send_email(task.email, subject, html_content)
  File "/home/data-engineer/GAAS_Data_System/venv/lib/python3.10/site-packages/airflow/utils/email.py", line 80, in send_email
    return backend(
  File "/home/data-engineer/GAAS_Data_System/venv/lib/python3.10/site-packages/airflow/utils/email.py", line 154, in send_email_smtp
    send_mime_email(e_from=mail_from, e_to=recipients, mime_msg=msg, conn_id=conn_id, dryrun=dryrun)
  File "/home/data-engineer/GAAS_Data_System/venv/lib/python3.10/site-packages/airflow/utils/email.py", line 272, in send_mime_email
    smtp_conn = _get_smtp_connection(smtp_host, smtp_port, smtp_timeout, smtp_ssl)
  File "/home/data-engineer/GAAS_Data_System/venv/lib/python3.10/site-packages/airflow/utils/email.py", line 317, in _get_smtp_connection
    return smtplib.SMTP(host=host, port=port, timeout=timeout)
  File "/usr/lib/python3.10/smtplib.py", line 255, in __init__
    (code, msg) = self.connect(host, port)
  File "/usr/lib/python3.10/smtplib.py", line 341, in connect
    self.sock = self._get_socket(host, port, self.timeout)
  File "/usr/lib/python3.10/smtplib.py", line 312, in _get_socket
    return socket.create_connection((host, port), timeout,
  File "/usr/lib/python3.10/socket.py", line 845, in create_connection
    raise err
  File "/usr/lib/python3.10/socket.py", line 833, in create_connection
    sock.connect(sa)
ConnectionRefusedError: [Errno 111] Connection refused

During handling of the above exception, another exception occurred:

Traceback (most recent call last):
  File "/home/data-engineer/GAAS_Data_System/venv/lib/python3.10/site-packages/airflow/models/taskinstance.py", line 2011, in handle_failure
    self.email_alert(error, task)
  File "/home/data-engineer/GAAS_Data_System/venv/lib/python3.10/site-packages/airflow/models/taskinstance.py", line 2428, in email_alert
    send_email(task.email, subject, html_content_err)
  File "/home/data-engineer/GAAS_Data_System/venv/lib/python3.10/site-packages/airflow/utils/email.py", line 80, in send_email
    return backend(
  File "/home/data-engineer/GAAS_Data_System/venv/lib/python3.10/site-packages/airflow/utils/email.py", line 154, in send_email_smtp
    send_mime_email(e_from=mail_from, e_to=recipients, mime_msg=msg, conn_id=conn_id, dryrun=dryrun)
  File "/home/data-engineer/GAAS_Data_System/venv/lib/python3.10/site-packages/airflow/utils/email.py", line 272, in send_mime_email
    smtp_conn = _get_smtp_connection(smtp_host, smtp_port, smtp_timeout, smtp_ssl)
  File "/home/data-engineer/GAAS_Data_System/venv/lib/python3.10/site-packages/airflow/utils/email.py", line 317, in _get_smtp_connection
    return smtplib.SMTP(host=host, port=port, timeout=timeout)
  File "/usr/lib/python3.10/smtplib.py", line 255, in __init__
    (code, msg) = self.connect(host, port)
  File "/usr/lib/python3.10/smtplib.py", line 341, in connect
    self.sock = self._get_socket(host, port, self.timeout)
  File "/usr/lib/python3.10/smtplib.py", line 312, in _get_socket
    return socket.create_connection((host, port), timeout,
  File "/usr/lib/python3.10/socket.py", line 845, in create_connection
    raise err
  File "/usr/lib/python3.10/socket.py", line 833, in create_connection
    sock.connect(sa)
ConnectionRefusedError: [Errno 111] Connection refused
[2023-08-25T17:54:38.178+0000] {standard_task_runner.py:104} ERROR - Failed to execute job 39 for task etl_event ([Errno 2] No such file or directory: '/home/data-engineer/GAAS_Data_System/ETL/cache_process/20230825'; 215459)
